Workbook

Sheet Data
A1: B/L# | B1: Shipment_ID | C1: Shipper | D1: Recipient | E1: Carrier | F1: Shipment_ready_date | G1: Pickup_date | H1: Wharehouse | I1: Destination | J1: ETA | K1: ATA | L1: Docs_Received | M1: Status | N1: Issue/Exception | O1: Commodity | P1: Notes | Q1: On_Time | R1: Processing_Days | S1: Delay_Flag | T1: Docs_Error
A2: BL-100001 | B2: 1 | C2: Target | D2: DC West | E2: UPS | F2: 45699 | G2: 45699 | H2: Chicago, IL | I2: Boston, MA | J2: 45700 | K2: 45701 | L2: y | M2: Picked_up | O2: Electronics | Q2: =IF(K2<=J2,1,0) -> 0 | R2: =(J2-F2) -> 1 | S2: =IF(M2="Delayed",1,0) -> 0 | T2: =IF(L2="n",1,0) -> 0
A3: BL-100002 | B3: 2 | C3: Target | D3: Hospital A | E3: UPS | F3: 45964 | G3: 45966 | H3: Los Angeles, CA | I3: Boston, MA | J3: 45967 | K3: 45969 | L3: y | M3: Delayed | N3: Mechanical issue | O3: Food Products | Q3: =IF(K3<=J3,1,0) -> 0 | R3: =(J3-F3) -> 3 | S3: =IF(M3="Delayed",1,0) -> 1 | T3: =IF(L3="n",1,0) -> 0
A4: BL-100003 | B4: 3 | C4: CVS | D4: Hospital A | E4: UPS | F4: 45852 | G4: 45852 | H4: Los Angeles, CA | I4: Boston, MA | J4: 45855 | K4: 45855 | L4: y | M4: Picked_up | O4: Industrial Parts | Q4: =IF(K4<=J4,1,0) -> 1 | R4: =(J4-F4) -> 3 | S4: =IF(M4="Delayed",1,0) -> 0 | T4: =IF(L4="n",1,0) -> 0
A5: BL-100004 | B5: 4 | C5: CVS | D5: Customer Direct | E5: USPS | F5: 45937 | G5: 45938 | H5: Dallas, TX | I5: Seattle, WA | J5: 45942 | K5: 45942 | L5: y | M5: Picked_up | O5: Auto Parts | Q5: =IF(K5<=J5,1,0) -> 1 | R5: =(J5-F5) -> 5 | S5: =IF(M5="Delayed",1,0) -> 0 | T5: =IF(L5="n",1,0) -> 0
A6: BL-100005 | B6: 5 | C6: Target | D6: Hospital A | E6: UPS | F6: 46008 | G6: 46009 | H6: Denver, CO | I6: Boston, MA | J6: 46014 | K6: 46017 | L6: n | M6: Delayed | N6: Carrier capacity | O6: Food Products | Q6: =IF(K6<=J6,1,0) -> 0 | R6: =(J6-F6) -> 6 | S6: =IF(M6="Delayed",1,0) -> 1 | T6: =IF(L6="n",1,0) -> 1
A7: BL-100006 | B7: 6 | C7: Target | D7: Hospital A | E7: USPS | F7: 45891 | G7: 45891 | H7: Dallas, TX | I7: Boston, MA | J7: 45895 | K7: 45896 | L7: y | M7: Delayed | N7: Routing error | O7: Food Products | Q7: =IF(K7<=J7,1,0) -> 0 | R7: =(J7-F7) -> 4 | S7: =IF(M7="Delayed",1,0) -> 1 | T7: =IF(L7="n",1,0) -> 0
A8: BL-100007 | B8: 7 | C8: Costco | D8: Pharmacy Hub | E8: XPO | F8: 45840 | G8: 45842 | H8: Denver, CO | I8: Atlanta, GA | J8: 45846 | K8: 45846 | L8: y | M8: Picked_up | O8: Auto Parts | Q8: =IF(K8<=J8,1,0) -> 1 | R8: =(J8-F8) -> 6 | S8: =IF(M8="Delayed",1,0) -> 0 | T8: =IF(L8="n",1,0) -> 0
A9: BL-100008 | B9: 8 | C9: Target | D9: Customer Direct | E9: DHL | F9: 45681 | G9: 45681 | H9: Dallas, TX | I9: Boston, MA | J9: 45685 | K9: 45685 | L9: y | M9: In_Transit | O9: Auto Parts | Q9: =IF(K9<=J9,1,0) -> 1 | R9: =(J9-F9) -> 4 | S9: =IF(M9="Delayed",1,0) -> 0 | T9: =IF(L9="n",1,0) -> 0
A10: BL-100009 | B10: 9 | C10: Walmart | D10: DC West | E10: FedEx | F10: 45789 | G10: 45791 | H10: Aurora, CO | I10: San Francisco, CA | J10: 45792 | K10: 45792 | L10: y | M10: In_Transit | O10: Industrial Parts | Q10: =IF(K10<=J10,1,0) -> 1 | R10: =(J10-F10) -> 3 | S10: =IF(M10="Delayed",1,0) -> 0 | T10: =IF(L10="n",1,0) -> 0
A11: BL-100010 | B11: 10 | C11: CVS | D11: Retail Store 12 | E11: USPS | F11: 45843 | G11: 45844 | H11: Denver, CO | I11: Atlanta, GA | J11: 45847 | K11: 45847 | L11: y | M11: In_Transit | O11: Industrial Parts | Q11: =IF(K11<=J11,1,0) -> 1 | R11: =(J11-F11) -> 4 | S11: =IF(M11="Delayed",1,0) -> 0 | T11: =IF(L11="n",1,0) -> 0
A12: BL-100011 | B12: 11 | C12: Walmart | D12: Pharmacy Hub | E12: UPS | F12: 45943 | G12: 45943 | H12: Chicago, IL | I12: Boston, MA | J12: 45945 | K12: 45947 | L12: n | M12: Delayed | N12: Mechanical issue | O12: Electronics | Q12: =IF(K12<=J12,1,0) -> 0 | R12: =(J12-F12) -> 2 | S12: =IF(M12="Delayed",1,0) -> 1 | T12: =IF(L12="n",1,0) -> 1
A13: BL-100012 | B13: 12 | C13: Costco | D13: Retail Store 12 | E13: USPS | F13: 45964 | G13: 45964 | H13: Chicago, IL | I13: Atlanta, GA | J13: 45968 | K13: 45972 | L13: y | M13: Delayed | N13: Address exception | O13: Electronics | Q13: =IF(K13<=J13,1,0) -> 0 | R13: =(J13-F13) -> 4 | S13: =IF(M13="Delayed",1,0) -> 1 | T13: =IF(L13="n",1,0) -> 0
A14: BL-100013 | B14: 13 | C14: Target | D14: DC West | E14: USPS | F14: 45813 | G14: 45813 | H14: Denver, CO | I14: San Francisco, CA | J14: 45818 | K14: 45818 | L14: y | M14: Picked_up | O14: Retail Goods | Q14: =IF(K14<=J14,1,0) -> 1 | R14: =(J14-F14) -> 5 | S14: =IF(M14="Delayed",1,0) -> 0 | T14: =IF(L14="n",1,0) -> 0
A15: BL-100014 | B15: 14 | C15: Costco | D15: Pharmacy Hub | E15: FedEx | F15: 45660 | G15: 45662 | H15: Los Angeles, CA | I15: Boston, MA | J15: 45665 | K15: 45665 | L15: y | M15: Picked_up | O15: Retail Goods | P15: Fragile - handle with care | Q15: =IF(K15<=J15,1,0) -> 1 | R15: =(J15-F15) -> 5 | S15: =IF(M15="Delayed",1,0) -> 0 | T15: =IF(L15="n",1,0) -> 0
A16: BL-100015 | B16: 15 | C16: CVS | D16: Pharmacy Hub | E16: DHL | F16: 45803 | G16: 45803 | H16: Chicago, IL | I16: Miami, FL | J16: 45806 | K16: 45806 | L16: y | M16: In_Transit | O16: Electronics | Q16: =IF(K16<=J16,1,0) -> 1 | R16: =(J16-F16) -> 3 | S16: =IF(M16="Delayed",1,0) -> 0 | T16: =IF(L16="n",1,0) -> 0
A17: BL-100016 | B17: 16 | C17: Walmart | D17: DC West | E17: FedEx | F17: 46003 | G17: 46004 | H17: Denver, CO | I17: San Francisco, CA | J17: 46008 | K17: 46010 | L17: y | M17: Delayed | N17: Hub congestion | O17: Food Products | P17: Call customer before delivery | Q17: =IF(K17<=J17,1,0) -> 0 | R17: =(J17-F17) -> 5 | S17: =IF(M17="Delayed",1,0) -> 1 | T17: =IF(L17="n",1,0) -> 0
A18: BL-100017 | B18: 17 | C18: Amazon | D18: Pharmacy Hub | E18: FedEx | F18: 45763 | G18: 45765 | H18: Dallas, TX | I18: San Francisco, CA | J18: 45766 | K18: 45766 | L18: n | M18: In_Transit | O18: Food Products | Q18: =IF(K18<=J18,1,0) -> 1 | R18: =(J18-F18) -> 3 | S18: =IF(M18="Delayed",1,0) -> 0 | T18: =IF(L18="n",1,0) -> 1
A19: BL-100018 | B19: 18 | C19: Target | D19: Customer Direct | E19: FedEx | F19: 45853 | G19: 45854 | H19: Denver, CO | I19: San Francisco, CA | J19: 45857 | K19: 45857 | L19: y | M19: Picked_up | O19: Retail Goods | Q19: =IF(K19<=J19,1,0) -> 1 | R19: =(J19-F19) -> 4 | S19: =IF(M19="Delayed",1,0) -> 0 | T19: =IF(L19="n",1,0) -> 0
A20: BL-100019 | B20: 19 | C20: Costco | D20: Customer Direct | E20: UPS | F20: 46003 | G20: 46003 | H20: Los Angeles, CA | I20: Miami, FL | J20: 46005 | K20: 46005 | L20: y | M20: Picked_up | O20: Medical Supplies | Q20: =IF(K20<=J20,1,0) -> 1 | R20: =(J20-F20) -> 2 | S20: =IF(M20="Delayed",1,0) -> 0 | T20: =IF(L20="n",1,0) -> 0
A21: BL-100020 | B21: 20 | C21: Costco | D21: DC West | E21: DHL | F21: 45667 | G21: 45669 | H21: Aurora, CO | I21: New York, NY | J21: 45672 | K21: 45672 | L21: y | M21: In_Transit | O21: Industrial Parts | Q21: =IF(K21<=J21,1,0) -> 1 | R21: =(J21-F21) -> 5 | S21: =IF(M21="Delayed",1,0) -> 0 | T21: =IF(L21="n",1,0) -> 0
A22: BL-100021 | B22: 21 | C22: Walmart | D22: Hospital A | E22: UPS | F22: 45927 | G22: 45929 | H22: Dallas, TX | I22: Phoenix, AZ | J22: 45931 | K22: 45931 | L22: y | M22: Picked_up | O22: Medical Supplies | Q22: =IF(K22<=J22,1,0) -> 1 | R22: =(J22-F22) -> 4 | S22: =IF(M22="Delayed",1,0) -> 0 | T22: =IF(L22="n",1,0) -> 0
A23: BL-100022 | B23: 22 | C23: Walmart | D23: Pharmacy Hub | E23: UPS | F23: 46009 | G23: 46009 | H23: Aurora, CO | I23: San Francisco, CA | J23: 46013 | K23: 46014 | L23: y | M23: Delayed | N23: Hub congestion | O23: Auto Parts | P23: Call customer before delivery | Q23: =IF(K23<=J23,1,0) -> 0 | R23: =(J23-F23) -> 4 | S23: =IF(M23="Delayed",1,0) -> 1 | T23: =IF(L23="n",1,0) -> 0
A24: BL-100023 | B24: 23 | C24: Amazon | D24: Retail Store 12 | E24: USPS | F24: 45762 | G24: 45763 | H24: Los Angeles, CA | I24: Phoenix, AZ | J24: 45767 | K24: 45767 | L24: n | M24: Picked_up | O24: Food Products | P24: Requires liftgate | Q24: =IF(K24<=J24,1,0) -> 1 | R24: =(J24-F24) -> 5 | S24: =IF(M24="Delayed",1,0) -> 0 | T24: =IF(L24="n",1,0) -> 1
A25: BL-100024 | B25: 24 | C25: Costco | D25: Customer Direct | E25: DHL | F25: 45887 | G25: 45887 | H25: Dallas, TX | I25: Seattle, WA | J25: 45892 | K25: 45893 | L25: y | M25: In_Transit | O25: Electronics | P25: Fragile - handle with care | Q25: =IF(K25<=J25,1,0) -> 0 | R25: =(J25-F25) -> 5 | S25: =IF(M25="Delayed",1,0) -> 0 | T25: =IF(L25="n",1,0) -> 0
A26: BL-100025 | B26: 25 | C26: Target | D26: Pharmacy Hub | E26: DHL | F26: 46014 | G26: 46016 | H26: Aurora, CO | I26: Miami, FL | J26: 46020 | K26: 46020 | L26: y | M26: In_Transit | O26: Electronics | Q26: =IF(K26<=J26,1,0) -> 1 | R26: =(J26-F26) -> 6 | S26: =IF(M26="Delayed",1,0) -> 0 | T26: =IF(L26="n",1,0) -> 0
A27: BL-100026 | B27: 26 | C27: Target | D27: Retail Store 12 | E27: FedEx | F27: 45739 | G27: 45740 | H27: Chicago, IL | I27: Seattle, WA | J27: 45744 | K27: 45744 | L27: y | M27: Picked_up | O27: Electronics | Q27: =IF(K27<=J27,1,0) -> 1 | R27: =(J27-F27) -> 5 | S27: =IF(M27="Delayed",1,0) -> 0 | T27: =IF(L27="n",1,0) -> 0
A28: BL-100027 | B28: 27 | C28: Walmart | D28: Pharmacy Hub | E28: UPS | F28: 45882 | G28: 45883 | H28: Aurora, CO | I28: New York, NY | J28: 45886 | K28: 45886 | L28: y | M28: Picked_up | O28: Electronics | P28: Temperature controlled | Q28: =IF(K28<=J28,1,0) -> 1 | R28: =(J28-F28) -> 4 | S28: =IF(M28="Delayed",1,0) -> 0 | T28: =IF(L28="n",1,0) -> 0
A29: BL-100028 | B29: 28 | C29: Walmart | D29: Hospital A | E29: USPS | F29: 45958 | G29: 45960 | H29: Los Angeles, CA | I29: Boston, MA | J29: 45965 | K29: 45965 | L29: y | M29: Picked_up | O29: Food Products | Q29: =IF(K29<=J29,1,0) -> 1 | R29: =(J29-F29) -> 7 | S29: =IF(M29="Delayed",1,0) -> 0 | T29: =IF(L29="n",1,0) -> 0
A30: BL-100029 | B30: 29 | C30: Walmart | D30: Hospital A | E30: USPS | F30: 45903 | G30: 45904 | H30: Aurora, CO | I30: New York, NY | J30: 45905 | K30: 45906 | L30: n | M30: In_Transit | O30: Auto Parts | Q30: =IF(K30<=J30,1,0) -> 0 | R30: =(J30-F30) -> 2 | S30: =IF(M30="Delayed",1,0) -> 0 | T30: =IF(L30="n",1,0) -> 1
A31: BL-100030 | B31: 30 | C31: CVS | D31: DC West | E31: XPO | F31: 45847 | G31: 45849 | H31: Denver, CO | I31: San Francisco, CA | J31: 45851 | K31: 45851 | L31: y | M31: In_Transit | O31: Medical Supplies | Q31: =IF(K31<=J31,1,0) -> 1 | R31: =(J31-F31) -> 4 | S31: =IF(M31="Delayed",1,0) -> 0 | T31: =IF(L31="n",1,0) -> 0
A32: BL-100031 | B32: 31 | C32: Amazon | D32: Customer Direct | E32: UPS | F32: 45769 | G32: 45769 | H32: Denver, CO | I32: Miami, FL | J32: 45770 | K32: 45770 | L32: y | M32: Picked_up | O32: Retail Goods | Q32: =IF(K32<=J32,1,0) -> 1 | R32: =(J32-F32) -> 1 | S32: =IF(M32="Delayed",1,0) -> 0 | T32: =IF(L32="n",1,0) -> 0
A33: BL-100032 | B33: 32 | C33: Walmart | D33: Retail Store 12 | E33: USPS | F33: 45860 | G33: 45862 | H33: Chicago, IL | I33: Miami, FL | J33: 45866 | K33: 45866 | L33: n | M33: In_Transit | O33: Medical Supplies | Q33: =IF(K33<=J33,1,0) -> 1 | R33: =(J33-F33) -> 6 | S33: =IF(M33="Delayed",1,0) -> 0 | T33: =IF(L33="n",1,0) -> 1
A34: BL-100033 | B34: 33 | C34: Costco | D34: Pharmacy Hub | E34: UPS | F34: 45813 | G34: 45814 | H34: Chicago, IL | I34: Atlanta, GA | J34: 45815 | K34: 45819 | L34: y | M34: Delayed | N34: Routing error | O34: Medical Supplies | Q34: =IF(K34<=J34,1,0) -> 0 | R34: =(J34-F34) -> 2 | S34: =IF(M34="Delayed",1,0) -> 1 | T34: =IF(L34="n",1,0) -> 0
A35: BL-100034 | B35: 34 | C35: CVS | D35: Retail Store 12 | E35: XPO | F35: 45840 | G35: 45841 | H35: Chicago, IL | I35: Seattle, WA | J35: 45844 | K35: 45844 | L35: y | M35: Picked_up | O35: Retail Goods | Q35: =IF(K35<=J35,1,0) -> 1 | R35: =(J35-F35) -> 4 | S35: =IF(M35="Delayed",1,0) -> 0 | T35: =IF(L35="n",1,0) -> 0
A36: BL-100035 | B36: 35 | C36: Costco | D36: Customer Direct | E36: FedEx | F36: 45809 | G36: 45810 | H36: Aurora, CO | I36: Boston, MA | J36: 45814 | K36: 45815 | L36: y | M36: Delayed | N36: Carrier capacity | O36: Electronics | Q36: =IF(K36<=J36,1,0) -> 0 | R36: =(J36-F36) -> 5 | S36: =IF(M36="Delayed",1,0) -> 1 | T36: =IF(L36="n",1,0) -> 0
A37: BL-100036 | B37: 36 | C37: Amazon | D37: Pharmacy Hub | E37: USPS | F37: 45962 | G37: 45963 | H37: Aurora, CO | I37: Miami, FL | J37: 45965 | K37: 45965 | L37: y | M37: In_Transit | O37: Industrial Parts | Q37: =IF(K37<=J37,1,0) -> 1 | R37: =(J37-F37) -> 3 | S37: =IF(M37="Delayed",1,0) -> 0 | T37: =IF(L37="n",1,0) -> 0
A38: BL-100037 | B38: 37 | C38: Target | D38: DC West | E38: DHL | F38: 45971 | G38: 45973 | H38: Los Angeles, CA | I38: San Francisco, CA | J38: 45975 | K38: 45975 | L38: y | M38: Picked_up | O38: Retail Goods | P38: Fragile - handle with care | Q38: =IF(K38<=J38,1,0) -> 1 | R38: =(J38-F38) -> 4 | S38: =IF(M38="Delayed",1,0) -> 0 | T38: =IF(L38="n",1,0) -> 0
A39: BL-100038 | B39: 38 | C39: Amazon | D39: Pharmacy Hub | E39: DHL | F39: 45780 | G39: 45780 | H39: Los Angeles, CA | I39: New York, NY | J39: 45783 | K39: 45785 | L39: y | M39: Delayed | N39: Address exception | O39: Industrial Parts | Q39: =IF(K39<=J39,1,0) -> 0 | R39: =(J39-F39) -> 3 | S39: =IF(M39="Delayed",1,0) -> 1 | T39: =IF(L39="n",1,0) -> 0
A40: BL-100039 | B40: 39 | C40: CVS | D40: DC West | E40: DHL | F40: 45872 | G40: 45874 | H40: Chicago, IL | I40: Phoenix, AZ | J40: 45875 | K40: 45875 | L40: y | M40: Picked_up | O40: Electronics | Q40: =IF(K40<=J40,1,0) -> 1 | R40: =(J40-F40) -> 3 | S40: =IF(M40="Delayed",1,0) -> 0 | T40: =IF(L40="n",1,0) -> 0
...

Sheet Dashboard
A1: Logistics KPI Dashboard
A3: KPI | B3: Value
A4: On-Time Delivery % | B4: =AVERAGE(Data!Q2:Q1201) -> 0.79083333
A5: Avg Processing Time (Days) | B5: =AVERAGE(Data!R2:R1201) -> 3.9858333
A6: Delay Rate % | B6: =AVERAGE(Data!S2:S1201) -> 0.1525
A7: Docs Error Rate % | B7: =AVERAGE(Data!T2:T1201) -> 0.19916667
A8: Total Shipments | B8: =COUNTA(Data!A2:A1201) -> 1200
A13: Delay Frequency by Carrier
A14: Carrier | B14: Delayed | C14: Total | D14: Delay Rate
A15: UPS | B15: =COUNTIFS(Data!E:E,A15,Data!S:S,1) -> 36 | C15: =COUNTIF(Data!E:E,A15) -> 230 | D15: =IF(C15=0,0,B15/C15) -> 0.15652174
A16: FedEx | B16: =COUNTIFS(Data!E:E,A16,Data!S:S,1) -> 35 | C16: =COUNTIF(Data!E:E,A16) -> 261 | D16: =IF(C16=0,0,B16/C16) -> 0.13409962
A17: XPO | B17: =COUNTIFS(Data!E:E,A17,Data!S:S,1) -> 36 | C17: =COUNTIF(Data!E:E,A17) -> 234 | D17: =IF(C17=0,0,B17/C17) -> 0.15384615
A18: DHL | B18: =COUNTIFS(Data!E:E,A18,Data!S:S,1) -> 38 | C18: =COUNTIF(Data!E:E,A18) -> 242 | D18: =IF(C18=0,0,B18/C18) -> 0.15702479
A19: USPS | B19: =COUNTIFS(Data!E:E,A19,Data!S:S,1) -> 38 | C19: =COUNTIF(Data!E:E,A19) -> 233 | D19: =IF(C19=0,0,B19/C19) -> 0.16309013
A27: Monthly On-Time % (Seasonality)
A28: Month | B28: On-Time % | F28: 45658 | G28: 45689
A29: Jan | B29: =AVERAGEIFS(Data!Q:Q,Data!G:G,">="&F28,Data!G:G,"<"&G28) -> 0.78571429 | F29: 45689 | G29: 45717
A30: Feb | B30: =AVERAGEIFS(Data!Q:Q,Data!G:G,">="&F29,Data!G:G,"<"&G29) -> 0.77586207 | F30: 45717 | G30: 45748
A31: Mar | B31: =AVERAGEIFS(Data!Q:Q,Data!G:G,">="&F30,Data!G:G,"<"&G30) -> 0.75 | F31: 45748 | G31: 45778
A32: Apr | B32: =AVERAGEIFS(Data!Q:Q,Data!G:G,">="&F31,Data!G:G,"<"&G31) -> 0.875 | F32: 45778 | G32: 45809
A33: May | B33: =AVERAGEIFS(Data!Q:Q,Data!G:G,">="&F32,Data!G:G,"<"&G32) -> 0.86021505 | F33: 45809 | G33: 45839
A34: Jun | B34: =AVERAGEIFS(Data!Q:Q,Data!G:G,">="&F33,Data!G:G,"<"&G33) -> 0.79411765 | F34: 45839 | G34: 45870
A35: Jul | B35: =AVERAGEIFS(Data!Q:Q,Data!G:G,">="&F34,Data!G:G,"<"&G34) -> 0.76767677 | F35: 45870 | G35: 45901
A36: Aug | B36: =AVERAGEIFS(Data!Q:Q,Data!G:G,">="&F35,Data!G:G,"<"&G35) -> 0.8019802 | F36: 45901 | G36: 45931
A37: Sep | B37: =AVERAGEIFS(Data!Q:Q,Data!G:G,">="&F36,Data!G:G,"<"&G36) -> 0.82978723 | F37: 45931 | G37: 45962
A38: Oct | B38: =AVERAGEIFS(Data!Q:Q,Data!G:G,">="&F37,Data!G:G,"<"&G37) -> 0.83505155 | F38: 45962 | G38: 45992
A39: Nov | B39: =AVERAGEIFS(Data!Q:Q,Data!G:G,">="&F38,Data!G:G,"<"&G38) -> 0.78321678 | F39: 45992 | G39: 46023
A40: Dec | B40: =AVERAGEIFS(Data!Q:Q,Data!G:G,">="&F39,Data!G:G,"<"&G39) -> 0.68531469
A46: Documentation Error Rate by Shipper
A47: Shipper | B47: Docs Error Rate
A48: Amazon | B48: =AVERAGEIFS(Data!S:S, Data!C:C, A48) -> 0.14746544
A49: Walmart | B49: =AVERAGEIFS(Data!S:S, Data!C:C, A49) -> 0.15447154
A50: CVS | B50: =AVERAGEIFS(Data!S:S, Data!C:C, A50) -> 0.14227642
A51: Target | B51: =AVERAGEIFS(Data!S:S, Data!C:C, A51) -> 0.15139442
A52: Costco | B52: =AVERAGEIFS(Data!S:S, Data!C:C, A52) -> 0.16666667
A58: Documentation Error Rate Over Time
A59: Month | B59: Docs Error %
A60: 01 | B60: =AVERAGEIFS(Data!T:T,Data!F:F,">="&DATE(2025,1,1),Data!F:F,"<"&EDATE(DATE(2025,1,1),1)) -> 0.1122449
A61: 02 | B61: =AVERAGEIFS(Data!T:T,Data!F:F,">="&DATE(2025,2,1),Data!F:F,"<"&EDATE(DATE(2025,2,1),1)) -> 0.17241379
A62: 03 | B62: =AVERAGEIFS(Data!T:T,Data!F:F,">="&DATE(2025,3,1),Data!F:F,"<"&EDATE(DATE(2025,3,1),1)) -> 0.27380952
...
